Workbook

Sheet Mod-1 Participant's Feedback
B2: Program | C2: Certified Manager of Quality / Organizational Excellence Batch - 12 (Date: 3rd to 08th Aug-2026 ) Module - 1
B3: Feedback Form | C3: Please rank the parameters on 10 to 1 scale | D3: 8 to 10 - Excellent ; 6 to 7 - V Good ; 4 to 5 - Good ; 2 to 3- Satisfactory ; 1 - Unsatisfactory
A4: Date | B4: KA / Subject (Name of Faculty) | C4: Criteria | D4: STAFF NO | U4: Avg | V4: Remarks
D5: 212845 | E5: 211110 | F5: 212784 | G5: 214358 | H5: 213762 | I5: 213962 | J5: 213338 | K5: 213949 | L5: 213526 | M5: E-213570 | N5: 210791 | O5: E-211125 | P5: 212856 | Q5: 213328 | R5: 823570 | S5: E211127 | T5: E213580
A6: DAY 1 (03-08-2026) | B6: Leadership (Part-I) Mr Surendra Singh, DGM (QM/BAE) | C6: Course Contenet | D6: 10 | E6: 9 | F6: 9 | G6: 10 | H6: 9 | I6: 9 | K6: 9 | L6: 10 | N6: 10 | Q6: 10 | R6: 9 | S6: 9 | T6: 9
C7: Structure & Flow | D7: 10 | E7: 9 | F7: 9 | G7: 10 | H7: 9 | I7: 9 | K7: 9 | L7: 10 | N7: 10 | Q7: 9 | R7: 9 | S7: 9 | T7: 9
C8: Time Management | D8: 10 | E8: 9 | F8: 9 | G8: 10 | H8: 9 | I8: 9 | K8: 9 | L8: 10 | N8: 10 | Q8: 9 | R8: 7 | S8: 10 | T8: 7
C9: Faculty Delivery | D9: 10 | E9: 9 | F9: 9 | G9: 10 | H9: 9 | I9: 9 | K9: 9 | L9: 10 | N9: 10 | Q9: 9 | R9: 9 | S9: 10 | T9: 9
C10: Faculty Participants Interaction | D10: 10 | E10: 9 | F10: 9 | G10: 10 | H10: 9 | I10: 9 | K10: 9 | L10: 10 | N10: 10 | Q10: 9 | R10: 9 | S10: 9 | T10: 9
B11: Strategic Plan Development & Deployment (Part-II) Mr Umesh Ghimirey, Sr.DGM (QM/BAE) | C11: Course Contenet | D11: 10 | E11: 9 | F11: 9 | G11: 10 | H11: 9 | I11: 9 | K11: 9 | L11: 10 | N11: 10 | Q11: 10 | R11: 10 | S11: 10 | T11: 10
C12: Structure & Flow | D12: 10 | E12: 9 | F12: 9 | G12: 10 | H12: 9 | I12: 9 | K12: 9 | L12: 10 | N12: 10 | Q12: 10 | R12: 10 | S12: 10 | T12: 9
C13: Time Management | D13: 10 | E13: 9 | F13: 9 | G13: 10 | H13: 9 | I13: 9 | K13: 9 | L13: 10 | N13: 10 | Q13: 10 | R13: 10 | S13: 10 | T13: 9
C14: Faculty Delivery | D14: 10 | E14: 9 | F14: 9 | G14: 10 | H14: 9 | I14: 9 | K14: 9 | L14: 10 | N14: 10 | Q14: 10 | R14: 10 | S14: 9 | T14: 9
C15: Faculty Participants Interaction | D15: 10 | E15: 9 | F15: 9 | G15: 10 | H15: 9 | I15: 9 | K15: 9 | L15: 10 | N15: 10 | Q15: 10 | R15: 10 | S15: 10 | T15: 10
A16: DAY 2 (04-08-2026) | B16: Leadership (Part-I) - Continuation Mr Surendra Singh , DGM (QM/BAE) | C16: Course Contenet | D16: 10 | E16: 10 | F16: 9 | G16: 10 | H16: 9 | I16: 9 | K16: 9 | L16: 10 | N16: 10 | Q16: 10 | R16: 10 | S16: 9 | T16: 10
C17: Structure & Flow | D17: 10 | E17: 9 | F17: 9 | G17: 10 | H17: 9 | I17: 9 | K17: 9 | L17: 10 | N17: 10 | Q17: 10 | R17: 10 | S17: 9 | T17: 9
C18: Time Management | D18: 10 | E18: 9 | F18: 9 | G18: 10 | H18: 9 | I18: 9 | K18: 9 | L18: 10 | N18: 10 | Q18: 10 | R18: 10 | S18: 10 | T18: 9
C19: Faculty Delivery | D19: 10 | E19: 9 | F19: 9 | G19: 10 | H19: 9 | I19: 9 | K19: 9 | L19: 10 | N19: 10 | Q19: 10 | R19: 10 | S19: 10 | T19: 9
C20: Faculty Participants Interaction | D20: 10 | E20: 10 | F20: 9 | G20: 10 | H20: 9 | I20: 9 | K20: 9 | L20: 10 | N20: 10 | Q20: 10 | R20: 10 | S20: 10 | T20: 9
B21: Strategic Plan Development & Deployment (Part-II)-Continuation Mr Umesh Ghimirey, Sr.DGM (QM/BAE) | C21: Course Contenet | D21: 10 | E21: 10 | F21: 9 | G21: 10 | H21: 9 | I21: 9 | K21: 9 | L21: 10 | N21: 10 | Q21: 10 | R21: 10 | S21: 10 | T21: 10
C22: Structure & Flow | D22: 10 | E22: 9 | F22: 9 | G22: 10 | H22: 9 | I22: 9 | K22: 9 | L22: 10 | N22: 10 | Q22: 10 | R22: 10 | S22: 9 | T22: 10
C23: Time Management | D23: 10 | E23: 9 | F23: 9 | G23: 10 | H23: 9 | I23: 9 | K23: 9 | L23: 10 | N23: 10 | Q23: 10 | R23: 10 | S23: 10 | T23: 10
C24: Faculty Delivery | D24: 10 | E24: 9 | F24: 9 | G24: 10 | H24: 9 | I24: 9 | K24: 9 | L24: 10 | N24: 10 | Q24: 10 | R24: 10 | S24: 10 | T24: 10
C25: Faculty Participants Interaction | D25: 10 | E25: 10 | F25: 9 | G25: 10 | H25: 9 | I25: 9 | K25: 9 | L25: 10 | N25: 10 | Q25: 10 | R25: 10 | S25: 10 | T25: 10
A26: DAY 3 (05-08-2026) | B26: Leadership (Part-I) Continuation Dr B Kishore (External Faculty) | C26: Course Contenet | D26: 10 | E26: 9 | F26: 9 | G26: 9 | H26: 9 | I26: 9 | K26: 9 | L26: 10 | N26: 10 | Q26: 10 | R26: 9 | S26: 9 | T26: 10
C27: Structure & Flow | D27: 10 | E27: 8 | F27: 9 | G27: 9 | H27: 9 | I27: 9 | K27: 9 | L27: 10 | N27: 9 | Q27: 10 | R27: 10 | S27: 9 | T27: 9
C28: Time Management | D28: 10 | E28: 10 | F28: 9 | G28: 9 | H28: 9 | I28: 9 | K28: 9 | L28: 10 | N28: 10 | Q28: 10 | R28: 10 | S28: 9 | T28: 10
C29: Faculty Delivery | D29: 10 | E29: 9 | F29: 9 | G29: 9 | H29: 9 | I29: 9 | K29: 9 | L29: 10 | N29: 10 | Q29: 10 | R29: 9 | S29: 9 | T29: 10
C30: Faculty Participants Interaction | D30: 10 | E30: 9 | F30: 9 | G30: 9 | H30: 9 | I30: 9 | K30: 9 | L30: 10 | N30: 9 | Q30: 10 | R30: 9 | S30: 9 | T30: 10
B31: Strategic Plan Development & Deployment (Part-II) Chap 7C Mr Umesh Ghimirey, Sr.DGM (QM/BAE) | C31: Course Contenet | D31: 10 | E31: 9 | F31: 9 | G31: 10 | H31: 9 | I31: 9 | K31: 9 | L31: 10 | N31: 10 | Q31: 10 | R31: 10 | S31: 9 | T31: 10
C32: Structure & Flow | D32: 10 | E32: 9 | F32: 9 | G32: 10 | H32: 9 | I32: 9 | K32: 9 | L32: 10 | N32: 10 | Q32: 10 | R32: 10 | S32: 9 | T32: 10
C33: Time Management | D33: 10 | E33: 9 | F33: 9 | G33: 10 | H33: 9 | I33: 9 | K33: 9 | L33: 10 | N33: 10 | Q33: 10 | R33: 10 | S33: 9 | T33: 10
C34: Faculty Delivery | D34: 10 | E34: 10 | F34: 9 | G34: 10 | H34: 9 | I34: 9 | K34: 9 | L34: 10 | N34: 10 | Q34: 10 | R34: 10 | S34: 9 | T34: 10
C35: Faculty Participants Interaction | D35: 10 | E35: 10 | F35: 9 | G35: 10 | H35: 9 | I35: 9 | K35: 9 | L35: 10 | N35: 10 | Q35: 10 | R35: 10 | S35: 9 | T35: 10
A36: DAY 4 (06-08-2026) | B36: Management Elements & Methods (Part-III-Chapter 8) Mr Jagadeesh Kumar R (External Faculty) | C36: Course Contenet | D36: 10 | E36: 9 | F36: 9 | G36: 10 | H36: 9 | I36: 9 | K36: 9 | L36: 9 | N36: 10 | Q36: 10 | R36: 10 | S36: 9 | T36: 10
C37: Structure & Flow | D37: 10 | E37: 9 | F37: 9 | G37: 10 | H37: 9 | I37: 9 | K37: 9 | L37: 9 | N37: 10 | Q37: 10 | R37: 9 | S37: 10 | T37: 10
C38: Time Management | D38: 10 | E38: 9 | F38: 9 | G38: 8 | H38: 9 | I38: 9 | K38: 9 | L38: 9 | N38: 10 | Q38: 10 | R38: 9 | S38: 10 | T38: 10
C39: Faculty Delivery | D39: 10 | E39: 10 | F39: 9 | G39: 10 | H39: 9 | I39: 9 | K39: 9 | L39: 9 | N39: 10 | Q39: 10 | R39: 9 | S39: 10 | T39: 10
C40: Faculty Participants Interaction | D40: 10 | E40: 10 | F40: 9 | G40: 10 | H40: 9 | I40: 9 | K40: 9 | L40: 9 | N40: 10 | Q40: 10 | R40: 10 | S40: 10 | T40: 10
B41: Chapter 8 - (Risks & Knowledgement Management) Mrs Anupama M, Sr.DGM (BG/NS(S&CS)) | C41: Course Contenet | D41: 10 | E41: 9 | F41: 8 | G41: 9 | H41: 9 | I41: 9 | K41: 9 | L41: 9 | N41: 9 | Q41: 10 | R41: 10 | S41: 9 | T41: 10
...

Sheet Mod-1 Overall Feedback
B4: Staff No | C4: ='Mod-1 Participant''s Feedback'!D5 | D4: ='Mod-1 Participant''s Feedback'!E5 | E4: ='Mod-1 Participant''s Feedback'!F5 | F4: ='Mod-1 Participant''s Feedback'!G5 | G4: ='Mod-1 Participant''s Feedback'!H5 | H4: ='Mod-1 Participant''s Feedback'!I5 | I4: ='Mod-1 Participant''s Feedback'!J5 | J4: ='Mod-1 Participant''s Feedback'!K5 | ... O4: ='Mod-1 Participant''s Feedback'!P5 | P4: ='Mod-1 Participant''s Feedback'!#REF! | Q4: ='Mod-1 Participant''s Feedback'!#REF! | R4: ='Mod-1 Participant''s Feedback'!#REF! | S4: ='Mod-1 Participant''s Feedback'!#REF! | T4: Average
B5: Delivery Notes (Course Material) | C5: ='Mod-1 Participant''s Feedback'!D75 | D5: ='Mod-1 Participant''s Feedback'!E75 | E5: ='Mod-1 Participant''s Feedback'!F75 | F5: ='Mod-1 Participant''s Feedback'!G75 | G5: ='Mod-1 Participant''s Feedback'!H75 | H5: ='Mod-1 Participant''s Feedback'!I75 | I5: ='Mod-1 Participant''s Feedback'!J75 | J5: ='Mod-1 Participant''s Feedback'!K75 | ... O5: ='Mod-1 Participant''s Feedback'!P75 | P5: ='Mod-1 Participant''s Feedback'!#REF! | Q5: ='Mod-1 Participant''s Feedback'!#REF! | R5: ='Mod-1 Participant''s Feedback'!#REF! | S5: ='Mod-1 Participant''s Feedback'!#REF! | T5: =AVERAGE(C5:S5)
B6: Communication & Overall Coordination | C6: ='Mod-1 Participant''s Feedback'!D76 | D6: ='Mod-1 Participant''s Feedback'!E76 | E6: ='Mod-1 Participant''s Feedback'!F76 | F6: ='Mod-1 Participant''s Feedback'!G76 | G6: ='Mod-1 Participant''s Feedback'!H76 | H6: ='Mod-1 Participant''s Feedback'!I76 | I6: ='Mod-1 Participant''s Feedback'!J76 | J6: ='Mod-1 Participant''s Feedback'!K76 | ... O6: ='Mod-1 Participant''s Feedback'!P76 | P6: ='Mod-1 Participant''s Feedback'!#REF! | Q6: ='Mod-1 Participant''s Feedback'!#REF! | R6: ='Mod-1 Participant''s Feedback'!#REF! | S6: ='Mod-1 Participant''s Feedback'!#REF! | T6: =AVERAGE(C6:S6)
B7: Classroom Facilities | C7: ='Mod-1 Participant''s Feedback'!D77 | D7: ='Mod-1 Participant''s Feedback'!E77 | E7: ='Mod-1 Participant''s Feedback'!F77 | F7: ='Mod-1 Participant''s Feedback'!G77 | G7: ='Mod-1 Participant''s Feedback'!H77 | H7: ='Mod-1 Participant''s Feedback'!I77 | I7: ='Mod-1 Participant''s Feedback'!J77 | J7: ='Mod-1 Participant''s Feedback'!K77 | ... O7: ='Mod-1 Participant''s Feedback'!P77 | P7: ='Mod-1 Participant''s Feedback'!#REF! | Q7: ='Mod-1 Participant''s Feedback'!#REF! | R7: ='Mod-1 Participant''s Feedback'!#REF! | S7: ='Mod-1 Participant''s Feedback'!#REF! | T7: =AVERAGE(C7:S7)
B8: Relevance to your current job | C8: ='Mod-1 Participant''s Feedback'!D78 | D8: ='Mod-1 Participant''s Feedback'!E78 | E8: ='Mod-1 Participant''s Feedback'!F78 | F8: ='Mod-1 Participant''s Feedback'!G78 | G8: ='Mod-1 Participant''s Feedback'!H78 | H8: ='Mod-1 Participant''s Feedback'!I78 | I8: ='Mod-1 Participant''s Feedback'!J78 | J8: ='Mod-1 Participant''s Feedback'!K78 | ... O8: ='Mod-1 Participant''s Feedback'!P78 | P8: ='Mod-1 Participant''s Feedback'!#REF! | Q8: ='Mod-1 Participant''s Feedback'!#REF! | R8: ='Mod-1 Participant''s Feedback'!#REF! | S8: ='Mod-1 Participant''s Feedback'!#REF! | T8: =AVERAGE(C8:S8)

Sheet Mod-1Suggestions
A1: Certified Manager of Quality / Organizational Excellence Batch - 12 (Date: 3rd to 08th Aug-2026 ) Module -1
A2: Overall Program Feedback
A3: SL No | B3: Staff No | C3: What are the other quality training programs you want us to add in training calendar ? | D3: Any Suggestions for the future program ?
A4: 1 | B4: =INDEX('Mod-1 Participant''s Feedback'!$D$5:$HS$5,ROW(A1)) | C4: =INDEX('Mod-1 Participant''s Feedback'!$D$79:$HS$79,ROW(A1)) | D4: =INDEX('Mod-1 Participant''s Feedback'!$D$80:$HS$80,ROW(A1))
A5: 2 | B5: =INDEX('Mod-1 Participant''s Feedback'!$D$5:$HS$5,ROW(A2)) | C5: =INDEX('Mod-1 Participant''s Feedback'!$D$79:$HS$79,ROW(A2)) | D5: =INDEX('Mod-1 Participant''s Feedback'!$D$80:$HS$80,ROW(A2))
A6: 3 | B6: =INDEX('Mod-1 Participant''s Feedback'!$D$5:$HS$5,ROW(A3)) | C6: =INDEX('Mod-1 Participant''s Feedback'!$D$79:$HS$79,ROW(A3)) | D6: =INDEX('Mod-1 Participant''s Feedback'!$D$80:$HS$80,ROW(A3))
A7: 4 | B7: =INDEX('Mod-1 Participant''s Feedback'!$D$5:$HS$5,ROW(A4)) | C7: =INDEX('Mod-1 Participant''s Feedback'!$D$79:$HS$79,ROW(A4)) | D7: =INDEX('Mod-1 Participant''s Feedback'!$D$80:$HS$80,ROW(A4))
A8: 5 | B8: =INDEX('Mod-1 Participant''s Feedback'!$D$5:$HS$5,ROW(A5)) | C8: =INDEX('Mod-1 Participant''s Feedback'!$D$79:$HS$79,ROW(A5)) | D8: =INDEX('Mod-1 Participant''s Feedback'!$D$80:$HS$80,ROW(A5))
A9: 6 | B9: =INDEX('Mod-1 Participant''s Feedback'!$D$5:$HS$5,ROW(A6)) | C9: =INDEX('Mod-1 Participant''s Feedback'!$D$79:$HS$79,ROW(A6)) | D9: =INDEX('Mod-1 Participant''s Feedback'!$D$80:$HS$80,ROW(A6))
A10: 7 | B10: =INDEX('Mod-1 Participant''s Feedback'!$D$5:$HS$5,ROW(A7)) | C10: =INDEX('Mod-1 Participant''s Feedback'!$D$79:$HS$79,ROW(A7)) | D10: =INDEX('Mod-1 Participant''s Feedback'!$D$80:$HS$80,ROW(A7)) | H10: -
A11: 8 | B11: =INDEX('Mod-1 Participant''s Feedback'!$D$5:$HS$5,ROW(A8)) | C11: =INDEX('Mod-1 Participant''s Feedback'!$D$79:$HS$79,ROW(A8)) | D11: =INDEX('Mod-1 Participant''s Feedback'!$D$80:$HS$80,ROW(A8))
A12: 9 | B12: =INDEX('Mod-1 Participant''s Feedback'!$D$5:$HS$5,ROW(A9)) | C12: =INDEX('Mod-1 Participant''s Feedback'!$D$79:$HS$79,ROW(A9)) | D12: =INDEX('Mod-1 Participant''s Feedback'!$D$80:$HS$80,ROW(A9))
A13: 10 | B13: =INDEX('Mod-1 Participant''s Feedback'!$D$5:$HS$5,ROW(A10)) | C13: =INDEX('Mod-1 Participant''s Feedback'!$D$79:$HS$79,ROW(A10)) | D13: =INDEX('Mod-1 Participant''s Feedback'!$D$80:$HS$80,ROW(A10))
A14: 11 | B14: =INDEX('Mod-1 Participant''s Feedback'!$D$5:$HS$5,ROW(A11)) | C14: =INDEX('Mod-1 Participant''s Feedback'!$D$79:$HS$79,ROW(A11)) | D14: =INDEX('Mod-1 Participant''s Feedback'!$D$80:$HS$80,ROW(A11))
A15: 12 | B15: =INDEX('Mod-1 Participant''s Feedback'!$D$5:$HS$5,ROW(A12)) | C15: =INDEX('Mod-1 Participant''s Feedback'!$D$79:$HS$79,ROW(A12)) | D15: =INDEX('Mod-1 Participant''s Feedback'!$D$80:$HS$80,ROW(A12))
A16: 13 | B16: =INDEX('Mod-1 Participant''s Feedback'!$D$5:$HS$5,ROW(A13)) | C16: =INDEX('Mod-1 Participant''s Feedback'!$D$79:$HS$79,ROW(A13)) | D16: =INDEX('Mod-1 Participant''s Feedback'!$D$80:$HS$80,ROW(A13))

Sheet Faculty Performance
A1: SS | B1: UG | C1: B K | D1: JK | E1: A M | F1: S K Das | G1: K V
A2: 9.3076923 | B2: 9.5384615 | C2: 9.3076923 | D2: 9.3076923 | E2: 8.8461538 | F2: 9.4615385 | G2: 9.3846154
A3: 9.3076923 | B3: 9.4615385 | C3: 9.3846154 | D3: 9.3076923 | E3: 8.6153846 | F3: 9.4615385 | G3: 9.4615385
A4: 9.0769231 | B4: 9.3846154 | C4: 9.4615385 | D4: 9.4615385 | E4: 8.6153846 | F4: 9.3846154 | G4: 9.5384615
A5: 9.0769231 | B5: 9.5384615 | C5: 9.3076923 | D5: 9.3846154 | E5: 8.6153846 | F5: 9.5384615 | G5: 9.4615385
A6: 9.3076923 | B6: 9.4615385 | C6: 9.3846154 | D6: 9.0769231 | E6: 8.5384615 | F6: 9.2307692 | G6: 9.3846154
A7: 9.3076923 | B7: 9.3846154 | D7: 9.3076923
A8: 9.4615385 | B8: 9.3076923 | D8: 9.3846154
A9: 9.3076923 | B9: 9.5384615 | D9: 9.5384615
A10: 9.3846154 | B10: 9.3076923 | D10: 9.3076923
A11: 9.3076923 | B11: 9.3076923 | D11: 9.3846154
A12: 9.6923077 | B12: 9.2307692
A13: 9.6153846 | B13: 9.5384615
A14: 9.6153846 | B14: 9.3076923
A15: 9.3846154 | B15: 9.4615385
A16: 9.3846154 | B16: 9.4
A17: 9.3846154 | B17: 9.3076923
A18: 9.4615385 | B18: 9.3846154
A19: 9.4615385 | B19: 9.6153846
A20: 9.5384615 | B20: 9.5384615
B21: 9.4615385
A22: =AVERAGE(A2:A21) | B22: =AVERAGE(B2:B21) | C22: =AVERAGE(C2:C21) | D22: =AVERAGE(D2:D21) | E22: =AVERAGE(E2:E21) | F22: =AVERAGE(F2:F21) | G22: =AVERAGE(G2:G21)
