Workbook

Sheet Mod-1 Participant's Feedback
B2: Program | C2: Certified Reliability Engineer - 30 (Date: 06th to 11th July-2026 ) Module - 1
B3: Feedback Form | C3: Please rank the parameters on 10 to 1 scale | D3: 8 to 10 - Excellent ; 6 to 7 - V Good ; 4 to 5 - Good ; 2 to 3- Satisfactory ; 1 - Unsatisfactory
A4: Date | B4: KA / Subject (Name of Faculty) | C4: Criteria | D4: STAFF NO | W4: Avg | X4: Remarks
D5: 218399 | E5: 216377 | F5: 502099-K | G5: 217755 | H5: 216676 | I5: 506104N | J5: 216322 | K5: 216168 | L5: 214004 | M5: 218036 | N5: 217847 | O5: 218033 | P5: 216448 | Q5: 216442 | R5: 217689 | S5: 216449 | T5: 216452 | U5: 217770 | V5: 218114
A6: DAY 1 (06-07-2026) | B6: Reliability Fundamentals (Leadership Foundations) (Mr Umesh Ghimirey, Sr.DGM (QM/BAE)) | C6: Course Contenet | D6: 10 | E6: 9 | F6: 10 | G6: 10 | H6: 10 | I6: 10 | J6: 10 | K6: 8 | L6: 9 | M6: 9 | N6: 8 | O6: 10 | P6: 10 | Q6: 9 | R6: 9 | S6: 10 | T6: 9 | U6: 9 | V6: 9 | W6: =AVERAGE(D6:V6) | X6: =IF(W6>=8,"Excellent",IF(W6>=6,"Very good",IF(W6>=4,"Good",IF(W6>=2,"Satisfactory",IF(W6>=1,"Unsatisfactory")))))
C7: Structure & Flow | D7: 8 | E7: 9 | F7: 10 | G7: 10 | H7: 10 | I7: 10 | J7: 10 | K7: 7 | L7: 8 | M7: 10 | N7: 10 | O7: 10 | P7: 10 | Q7: 10 | R7: 10 | S7: 10 | T7: 9 | U7: 9 | V7: 9 | W7: =AVERAGE(D7:V7) | X7: =IF(W7>=8,"Excellent",IF(W7>=6,"Very good",IF(W7>=4,"Good",IF(W7>=2,"Satisfactory",IF(W7>=1,"Unsatisfactory")))))
C8: Time Management | D8: 8 | E8: 10 | F8: 10 | G8: 10 | H8: 10 | I8: 10 | J8: 10 | K8: 10 | L8: 10 | M8: 10 | N8: 9 | O8: 10 | P8: 10 | Q8: 10 | R8: 10 | S8: 10 | T8: 9 | U8: 8 | V8: 9 | W8: =AVERAGE(D8:V8) | X8: =IF(W8>=8,"Excellent",IF(W8>=6,"Very good",IF(W8>=4,"Good",IF(W8>=2,"Satisfactory",IF(W8>=1,"Unsatisfactory")))))
C9: Faculty Delivery | D9: 8 | E9: 8 | F9: 10 | G9: 10 | H9: 10 | I9: 10 | J9: 10 | K9: 8 | L9: 8 | M9: 10 | N9: 10 | O9: 10 | P9: 10 | Q9: 10 | R9: 10 | S9: 10 | T9: 9 | U9: 9 | V9: 9 | W9: =AVERAGE(D9:V9) | X9: =IF(W9>=8,"Excellent",IF(W9>=6,"Very good",IF(W9>=4,"Good",IF(W9>=2,"Satisfactory",IF(W9>=1,"Unsatisfactory")))))
C10: Faculty Participants Interaction | D10: 9 | E10: 10 | F10: 10 | G10: 10 | H10: 9 | I10: 10 | J10: 10 | K10: 8 | L10: 8 | M10: 10 | N10: 10 | O10: 10 | P10: 10 | Q10: 9 | R10: 10 | S10: 10 | T10: 9 | U10: 9 | V10: 9 | W10: =AVERAGE(D10:V10) | X10: =IF(W10>=8,"Excellent",IF(W10>=6,"Very good",IF(W10>=4,"Good",IF(W10>=2,"Satisfactory",IF(W10>=1,"Unsatisfactory")))))
B11: Risk Management (Mr Jagadeesh Kumar R ) | C11: Course Contenet | D11: 10 | E11: 9 | F11: 9 | G11: 10 | H11: 8 | I11: 10 | J11: 10 | K11: 8 | L11: 6 | M11: 9 | N11: 9 | O11: 10 | P11: 8 | Q11: 9 | R11: 9 | S11: 10 | T11: 7 | U11: 9 | V11: 9 | W11: =AVERAGE(D11:V11) | X11: =IF(W11>=8,"Excellent",IF(W11>=6,"Very good",IF(W11>=4,"Good",IF(W11>=2,"Satisfactory",IF(W11>=1,"Unsatisfactory")))))
C12: Structure & Flow | D12: 8 | E12: 3 | F12: 9 | G12: 10 | H12: 8 | I12: 10 | J12: 10 | K12: 7 | L12: 8 | M12: 9 | N12: 8 | O12: 10 | P12: 8 | Q12: 9 | R12: 10 | S12: 10 | T12: 6 | U12: 9 | V12: 9 | W12: =AVERAGE(D12:V12) | X12: =IF(W12>=8,"Excellent",IF(W12>=6,"Very good",IF(W12>=4,"Good",IF(W12>=2,"Satisfactory",IF(W12>=1,"Unsatisfactory")))))
C13: Time Management | D13: 7 | E13: 3 | F13: 9 | G13: 10 | H13: 8 | I13: 10 | J13: 10 | K13: 10 | L13: 10 | M13: 9 | N13: 9 | O13: 7 | P13: 9 | Q13: 9 | R13: 10 | S13: 10 | T13: 8 | U13: 8 | V13: 9 | W13: =AVERAGE(D13:V13) | X13: =IF(W13>=8,"Excellent",IF(W13>=6,"Very good",IF(W13>=4,"Good",IF(W13>=2,"Satisfactory",IF(W13>=1,"Unsatisfactory")))))
C14: Faculty Delivery | D14: 7 | E14: 7 | F14: 9 | G14: 10 | H14: 8 | I14: 10 | J14: 10 | K14: 8 | L14: 7 | M14: 10 | N14: 10 | O14: 10 | P14: 9 | Q14: 10 | R14: 9 | S14: 10 | T14: 6 | U14: 9 | V14: 9 | W14: =AVERAGE(D14:V14) | X14: =IF(W14>=8,"Excellent",IF(W14>=6,"Very good",IF(W14>=4,"Good",IF(W14>=2,"Satisfactory",IF(W14>=1,"Unsatisfactory")))))
C15: Faculty Participants Interaction | D15: 8 | E15: 3 | F15: 9 | G15: 10 | H15: 8 | I15: 10 | J15: 10 | K15: 8 | L15: 7 | M15: 10 | N15: 9 | O15: 10 | P15: 8 | Q15: 9 | R15: 10 | S15: 10 | T15: 6 | U15: 9 | V15: 9 | W15: =AVERAGE(D15:V15) | X15: =IF(W15>=8,"Excellent",IF(W15>=6,"Very good",IF(W15>=4,"Good",IF(W15>=2,"Satisfactory",IF(W15>=1,"Unsatisfactory")))))
A16: DAY 2 (07-07-2026) | B16: Reliability Fundamentals (Reliability Foundations) (Mr Umesh Ghimirey, Sr.DGM (QM/BAE)) | C16: Course Contenet | D16: 10 | E16: 9 | F16: 10 | G16: 10 | H16: 9 | I16: 10 | J16: 10 | K16: 7 | L16: 6 | M16: 10 | N16: 10 | O16: 10 | P16: 10 | Q16: 9 | R16: 9 | S16: 10 | T16: 9 | U16: 9 | V16: 9 | W16: =AVERAGE(D16:V16) | X16: =IF(W16>=8,"Excellent",IF(W16>=6,"Very good",IF(W16>=4,"Good",IF(W16>=2,"Satisfactory",IF(W16>=1,"Unsatisfactory")))))
C17: Structure & Flow | D17: 8 | E17: 9 | F17: 10 | G17: 10 | H17: 9 | I17: 10 | J17: 10 | K17: 8 | L17: 7 | M17: 9 | N17: 10 | O17: 10 | P17: 10 | Q17: 10 | R17: 10 | S17: 9 | T17: 10 | U17: 9 | V17: 9 | W17: =AVERAGE(D17:V17) | X17: =IF(W17>=8,"Excellent",IF(W17>=6,"Very good",IF(W17>=4,"Good",IF(W17>=2,"Satisfactory",IF(W17>=1,"Unsatisfactory")))))
C18: Time Management | D18: 7 | E18: 10 | F18: 10 | G18: 10 | H18: 10 | I18: 10 | J18: 10 | K18: 9 | L18: 10 | M18: 10 | N18: 10 | O18: 10 | P18: 10 | Q18: 10 | R18: 10 | S18: 10 | T18: 10 | U18: 8 | V18: 9 | W18: =AVERAGE(D18:V18) | X18: =IF(W18>=8,"Excellent",IF(W18>=6,"Very good",IF(W18>=4,"Good",IF(W18>=2,"Satisfactory",IF(W18>=1,"Unsatisfactory")))))
C19: Faculty Delivery | D19: 7 | E19: 8 | F19: 10 | G19: 10 | H19: 9 | I19: 10 | J19: 10 | K19: 9 | L19: 7 | M19: 10 | N19: 10 | O19: 10 | P19: 10 | Q19: 10 | R19: 10 | S19: 10 | T19: 9 | U19: 9 | V19: 9 | W19: =AVERAGE(D19:V19) | X19: =IF(W19>=8,"Excellent",IF(W19>=6,"Very good",IF(W19>=4,"Good",IF(W19>=2,"Satisfactory",IF(W19>=1,"Unsatisfactory")))))
C20: Faculty Participants Interaction | D20: 9 | E20: 10 | F20: 10 | G20: 10 | H20: 9 | I20: 10 | J20: 10 | K20: 9 | L20: 8 | M20: 9 | N20: 10 | O20: 10 | P20: 10 | Q20: 9 | R20: 10 | S20: 10 | T20: 9 | U20: 9 | V20: 9 | W20: =AVERAGE(D20:V20) | X20: =IF(W20>=8,"Excellent",IF(W20>=6,"Very good",IF(W20>=4,"Good",IF(W20>=2,"Satisfactory",IF(W20>=1,"Unsatisfactory")))))
B21: Probability & Statistics for Reliability (Basic Concepts) (Mr Narendra S, MGR (BG/PDIC)) | C21: Course Contenet | D21: 10 | E21: 10 | F21: 10 | G21: 10 | H21: 9 | I21: 10 | J21: 10 | K21: 7 | L21: 6 | M21: 10 | N21: 10 | O21: 10 | P21: 10 | Q21: 9 | R21: 9 | S21: 10 | T21: 9 | U21: 9 | V21: 9 | W21: =AVERAGE(D21:V21) | X21: =IF(W21>=8,"Excellent",IF(W21>=6,"Very good",IF(W21>=4,"Good",IF(W21>=2,"Satisfactory",IF(W21>=1,"Unsatisfactory")))))
C22: Structure & Flow | D22: 9 | E22: 9 | F22: 10 | G22: 10 | H22: 9 | I22: 10 | J22: 10 | K22: 8 | L22: 7 | M22: 9 | N22: 10 | O22: 10 | P22: 10 | Q22: 9 | R22: 10 | S22: 9 | T22: 9 | U22: 9 | V22: 9 | W22: =AVERAGE(D22:V22) | X22: =IF(W22>=8,"Excellent",IF(W22>=6,"Very good",IF(W22>=4,"Good",IF(W22>=2,"Satisfactory",IF(W22>=1,"Unsatisfactory")))))
C23: Time Management | D23: 9 | E23: 10 | F23: 10 | G23: 10 | H23: 9 | I23: 10 | J23: 10 | K23: 9 | L23: 10 | M23: 10 | N23: 10 | O23: 10 | P23: 10 | Q23: 9 | R23: 10 | S23: 10 | T23: 9 | U23: 9 | V23: 9 | W23: =AVERAGE(D23:V23) | X23: =IF(W23>=8,"Excellent",IF(W23>=6,"Very good",IF(W23>=4,"Good",IF(W23>=2,"Satisfactory",IF(W23>=1,"Unsatisfactory")))))
C24: Faculty Delivery | D24: 9 | E24: 10 | F24: 10 | G24: 10 | H24: 9 | I24: 10 | J24: 10 | K24: 9 | L24: 7 | M24: 10 | N24: 10 | O24: 10 | P24: 10 | Q24: 10 | R24: 10 | S24: 9 | T24: 9 | U24: 9 | V24: 9 | W24: =AVERAGE(D24:V24) | X24: =IF(W24>=8,"Excellent",IF(W24>=6,"Very good",IF(W24>=4,"Good",IF(W24>=2,"Satisfactory",IF(W24>=1,"Unsatisfactory")))))
C25: Faculty Participants Interaction | D25: 8 | E25: 9 | F25: 10 | G25: 10 | H25: 9 | I25: 10 | J25: 10 | K25: 9 | L25: 7 | M25: 10 | N25: 10 | O25: 10 | P25: 10 | Q25: 9 | R25: 10 | S25: 10 | T25: 9 | U25: 8 | V25: 9 | W25: =AVERAGE(D25:V25) | X25: =IF(W25>=8,"Excellent",IF(W25>=6,"Very good",IF(W25>=4,"Good",IF(W25>=2,"Satisfactory",IF(W25>=1,"Unsatisfactory")))))
A26: DAY 3 (08-07-2026) | B26: Reliability Fundamentals (Reliability Foundations) (Mr Umesh Ghimirey, Sr.DGM (QM/BAE)) | C26: Course Contenet | D26: 9 | E26: 9 | F26: 10 | G26: 10 | H26: 9 | I26: 10 | J26: 10 | K26: 8 | L26: 7 | M26: 10 | N26: 10 | O26: 10 | P26: 10 | Q26: 9 | R26: 10 | S26: 9 | T26: 9 | U26: 9 | V26: 9 | W26: =AVERAGE(D26:V26) | X26: =IF(W26>=8,"Excellent",IF(W26>=6,"Very good",IF(W26>=4,"Good",IF(W26>=2,"Satisfactory",IF(W26>=1,"Unsatisfactory")))))
C27: Structure & Flow | D27: 9 | E27: 9 | F27: 10 | G27: 10 | H27: 9 | I27: 10 | J27: 10 | K27: 8 | L27: 7 | M27: 10 | N27: 9 | O27: 10 | P27: 10 | Q27: 10 | R27: 10 | S27: 10 | T27: 9 | U27: 9 | V27: 9 | W27: =AVERAGE(D27:V27) | X27: =IF(W27>=8,"Excellent",IF(W27>=6,"Very good",IF(W27>=4,"Good",IF(W27>=2,"Satisfactory",IF(W27>=1,"Unsatisfactory")))))
C28: Time Management | D28: 9 | E28: 10 | F28: 10 | G28: 10 | H28: 9 | I28: 10 | J28: 10 | K28: 9 | L28: 10 | M28: 9 | N28: 9 | O28: 10 | P28: 10 | Q28: 10 | R28: 10 | S28: 9 | T28: 9 | U28: 9 | V28: 9 | W28: =AVERAGE(D28:V28) | X28: =IF(W28>=8,"Excellent",IF(W28>=6,"Very good",IF(W28>=4,"Good",IF(W28>=2,"Satisfactory",IF(W28>=1,"Unsatisfactory")))))
C29: Faculty Delivery | D29: 8 | E29: 8 | F29: 10 | G29: 10 | H29: 9 | I29: 10 | J29: 10 | K29: 8 | L29: 7 | M29: 10 | N29: 10 | O29: 10 | P29: 10 | Q29: 10 | R29: 10 | S29: 9 | T29: 9 | U29: 9 | V29: 9 | W29: =AVERAGE(D29:V29) | X29: =IF(W29>=8,"Excellent",IF(W29>=6,"Very good",IF(W29>=4,"Good",IF(W29>=2,"Satisfactory",IF(W29>=1,"Unsatisfactory")))))
C30: Faculty Participants Interaction | D30: 9 | E30: 10 | F30: 10 | G30: 10 | H30: 10 | I30: 10 | J30: 10 | K30: 8 | L30: 8 | M30: 10 | N30: 10 | O30: 10 | P30: 10 | Q30: 9 | R30: 10 | S30: 10 | T30: 9 | U30: 9 | V30: 9 | W30: =AVERAGE(D30:V30) | X30: =IF(W30>=8,"Excellent",IF(W30>=6,"Very good",IF(W30>=4,"Good",IF(W30>=2,"Satisfactory",IF(W30>=1,"Unsatisfactory")))))
B31: Probability & Statistics for Reliability (Probability Distributions & Functions) (Mr Surendra Singh DGM (QM/BAE)) | C31: Course Contenet | D31: 10 | E31: 7 | F31: 10 | G31: 10 | H31: 9 | I31: 10 | J31: 10 | K31: 8 | L31: 6 | M31: 10 | N31: 10 | O31: 10 | P31: 10 | Q31: 9 | R31: 10 | S31: 9 | T31: 8 | U31: 9 | V31: 9 | W31: =AVERAGE(D31:V31) | X31: =IF(W31>=8,"Excellent",IF(W31>=6,"Very good",IF(W31>=4,"Good",IF(W31>=2,"Satisfactory",IF(W31>=1,"Unsatisfactory")))))
C32: Structure & Flow | D32: 9 | E32: 6 | F32: 10 | G32: 10 | H32: 9 | I32: 10 | J32: 10 | K32: 7 | L32: 6 | M32: 9 | N32: 10 | O32: 10 | P32: 10 | Q32: 10 | R32: 10 | S32: 10 | T32: 8 | U32: 9 | V32: 9 | W32: =AVERAGE(D32:V32) | X32: =IF(W32>=8,"Excellent",IF(W32>=6,"Very good",IF(W32>=4,"Good",IF(W32>=2,"Satisfactory",IF(W32>=1,"Unsatisfactory")))))
C33: Time Management | D33: 9 | E33: 9 | F33: 10 | G33: 10 | H33: 9 | I33: 10 | J33: 10 | K33: 8 | L33: 10 | M33: 10 | N33: 9 | O33: 10 | P33: 10 | Q33: 10 | R33: 10 | S33: 10 | T33: 9 | U33: 9 | V33: 9 | W33: =AVERAGE(D33:V33) | X33: =IF(W33>=8,"Excellent",IF(W33>=6,"Very good",IF(W33>=4,"Good",IF(W33>=2,"Satisfactory",IF(W33>=1,"Unsatisfactory")))))
C34: Faculty Delivery | D34: 8 | E34: 5 | F34: 10 | G34: 10 | H34: 9 | I34: 10 | J34: 10 | K34: 8 | L34: 7 | M34: 10 | N34: 10 | O34: 10 | P34: 10 | Q34: 10 | R34: 10 | S34: 10 | T34: 8 | U34: 9 | V34: 9 | W34: =AVERAGE(D34:V34) | X34: =IF(W34>=8,"Excellent",IF(W34>=6,"Very good",IF(W34>=4,"Good",IF(W34>=2,"Satisfactory",IF(W34>=1,"Unsatisfactory")))))
C35: Faculty Participants Interaction | D35: 9 | E35: 6 | F35: 10 | G35: 10 | H35: 9 | I35: 10 | J35: 10 | K35: 8 | L35: 7 | M35: 9 | N35: 10 | O35: 10 | P35: 10 | Q35: 9 | R35: 10 | S35: 10 | T35: 8 | U35: 9 | V35: 9 | W35: =AVERAGE(D35:V35) | X35: =IF(W35>=8,"Excellent",IF(W35>=6,"Very good",IF(W35>=4,"Good",IF(W35>=2,"Satisfactory",IF(W35>=1,"Unsatisfactory")))))
A36: DAY 4 (09-07-2026) | B36: Probability & Statistics for Reliability (Sampling Plans, SPC, Cp, Cpk) (Mrs Pidathal Jahnavi DM (BG/MS)) | C36: Course Contenet | D36: 10 | E36: 7 | F36: 8 | G36: 10 | H36: 9 | I36: 10 | J36: 10 | K36: 8 | L36: 6 | M36: 9 | N36: 9 | O36: 10 | P36: 10 | Q36: 9 | R36: 9 | S36: 10 | T36: 7 | U36: 9 | V36: 9 | W36: =AVERAGE(D36:V36) | X36: =IF(W36>=8,"Excellent",IF(W36>=6,"Very good",IF(W36>=4,"Good",IF(W36>=2,"Satisfactory",IF(W36>=1,"Unsatisfactory")))))
C37: Structure & Flow | D37: 8 | E37: 7 | F37: 8 | G37: 10 | H37: 8 | I37: 10 | J37: 10 | K37: 7 | L37: 6 | M37: 9 | N37: 9 | O37: 10 | P37: 10 | Q37: 9 | R37: 9 | S37: 10 | T37: 6 | U37: 9 | V37: 9 | W37: =AVERAGE(D37:V37) | X37: =IF(W37>=8,"Excellent",IF(W37>=6,"Very good",IF(W37>=4,"Good",IF(W37>=2,"Satisfactory",IF(W37>=1,"Unsatisfactory")))))
C38: Time Management | D38: 8 | E38: 9 | F38: 8 | G38: 10 | H38: 8 | I38: 10 | J38: 10 | K38: 8 | L38: 10 | M38: 10 | N38: 9 | O38: 9 | P38: 10 | Q38: 10 | R38: 9 | S38: 10 | T38: 6 | U38: 9 | V38: 9 | W38: =AVERAGE(D38:V38) | X38: =IF(W38>=8,"Excellent",IF(W38>=6,"Very good",IF(W38>=4,"Good",IF(W38>=2,"Satisfactory",IF(W38>=1,"Unsatisfactory")))))
C39: Faculty Delivery | D39: 9 | E39: 7 | F39: 8 | G39: 10 | H39: 8 | I39: 10 | J39: 10 | K39: 7 | L39: 6 | M39: 9 | N39: 10 | O39: 10 | P39: 9 | Q39: 9 | R39: 9 | S39: 10 | T39: 6 | U39: 9 | V39: 9 | W39: =AVERAGE(D39:V39) | X39: =IF(W39>=8,"Excellent",IF(W39>=6,"Very good",IF(W39>=4,"Good",IF(W39>=2,"Satisfactory",IF(W39>=1,"Unsatisfactory")))))
C40: Faculty Participants Interaction | D40: 9 | E40: 7 | F40: 8 | G40: 10 | H40: 7 | I40: 10 | J40: 10 | K40: 7 | L40: 6 | M40: 10 | N40: 10 | O40: 10 | P40: 10 | Q40: 9 | R40: 9 | S40: 10 | T40: 6 | U40: 9 | V40: 9 | W40: =AVERAGE(D40:V40) | X40: =IF(W40>=8,"Excellent",IF(W40>=6,"Very good",IF(W40>=4,"Good",IF(W40>=2,"Satisfactory",IF(W40>=1,"Unsatisfactory")))))
B41: Probability & Statistics for Reliability (Confidence & Tolerance Intervals, Test of Hypothesis, ANOVA) (Mr Surendra Singh DGM (QM/BAE)) | C41: Course Contenet | D41: 10 | E41: 7 | F41: 9 | G41: 10 | H41: 9 | I41: 10 | J41: 10 | K41: 8 | L41: 6 | M41: 10 | N41: 10 | O41: 10 | P41: 10 | Q41: 10 | R41: 9 | S41: 10 | T41: 8 | U41: 9 | V41: 9 | W41: =AVERAGE(D41:V41) | X41: =IF(W41>=8,"Excellent",IF(W41>=6,"Very good",IF(W41>=4,"Good",IF(W41>=2,"Satisfactory",IF(W41>=1,"Unsatisfactory")))))
...

Sheet Mod-1 Overall Feedback
B4: Staff No | C4: 218399 | D4: ='Mod-1 Participant''s Feedback'!E5 | E4: ='Mod-1 Participant''s Feedback'!F5 | F4: ='Mod-1 Participant''s Feedback'!G5 | G4: ='Mod-1 Participant''s Feedback'!H5 | H4: ='Mod-1 Participant''s Feedback'!I5 | I4: ='Mod-1 Participant''s Feedback'!J5 | J4: ='Mod-1 Participant''s Feedback'!K5 | K4: ='Mod-1 Participant''s Feedback'!L5 | ... U4: ='Mod-1 Participant''s Feedback'!V5 | V4: Average
B5: Delivery Notes (Course Material) | V5: =AVERAGE(C5:U5)
B6: Communication & Overall Coordination | V6: =AVERAGE(C6:U6)
B7: Classroom Facilities | V7: =AVERAGE(C7:U7)
B8: Relevance to your current job | V8: =AVERAGE(C8:U8)

Sheet Mod-1Suggestions
A1: Basic Project Mnagement Batch - 04 (Date: 9th to 11th Jun-2026 )
A2: Overall Program Feedback
A3: SL No | B3: Staff No | C3: What are the other quality training programs you want us to add in training calender ? | D3: Any Suggestions for the future program ?
A4: 1 | B4: =INDEX('Mod-1 Participant''s Feedback'!$D$5:$HY$5,ROW(A1)) | C4: =INDEX('Mod-1 Participant''s Feedback'!$D$59:$HY$59,ROW(A1)) | D4: =INDEX('Mod-1 Participant''s Feedback'!$D$60:$HY$60,ROW(A1))
A5: 2 | B5: =INDEX('Mod-1 Participant''s Feedback'!$D$5:$HY$5,ROW(A2)) | C5: =INDEX('Mod-1 Participant''s Feedback'!$D$59:$HY$59,ROW(A2)) | D5: =INDEX('Mod-1 Participant''s Feedback'!$D$60:$HY$60,ROW(A2))
A6: 3 | B6: =INDEX('Mod-1 Participant''s Feedback'!$D$5:$HY$5,ROW(A3)) | C6: =INDEX('Mod-1 Participant''s Feedback'!$D$59:$HY$59,ROW(A3)) | D6: =INDEX('Mod-1 Participant''s Feedback'!$D$60:$HY$60,ROW(A3))
A7: 4 | B7: =INDEX('Mod-1 Participant''s Feedback'!$D$5:$HY$5,ROW(A4)) | C7: =INDEX('Mod-1 Participant''s Feedback'!$D$59:$HY$59,ROW(A4)) | D7: =INDEX('Mod-1 Participant''s Feedback'!$D$60:$HY$60,ROW(A4))
A8: 5 | B8: =INDEX('Mod-1 Participant''s Feedback'!$D$5:$HY$5,ROW(A5)) | C8: =INDEX('Mod-1 Participant''s Feedback'!$D$59:$HY$59,ROW(A5)) | D8: =INDEX('Mod-1 Participant''s Feedback'!$D$60:$HY$60,ROW(A5))
A9: 6 | B9: =INDEX('Mod-1 Participant''s Feedback'!$D$5:$HY$5,ROW(A6)) | C9: =INDEX('Mod-1 Participant''s Feedback'!$D$59:$HY$59,ROW(A6)) | D9: =INDEX('Mod-1 Participant''s Feedback'!$D$60:$HY$60,ROW(A6))
A10: 7 | B10: =INDEX('Mod-1 Participant''s Feedback'!$D$5:$HY$5,ROW(A7)) | C10: =INDEX('Mod-1 Participant''s Feedback'!$D$59:$HY$59,ROW(A7)) | D10: =INDEX('Mod-1 Participant''s Feedback'!$D$60:$HY$60,ROW(A7)) | H10: -
A11: 8 | B11: =INDEX('Mod-1 Participant''s Feedback'!$D$5:$HY$5,ROW(A8)) | C11: =INDEX('Mod-1 Participant''s Feedback'!$D$59:$HY$59,ROW(A8)) | D11: =INDEX('Mod-1 Participant''s Feedback'!$D$60:$HY$60,ROW(A8))
A12: 9 | B12: =INDEX('Mod-1 Participant''s Feedback'!$D$5:$HY$5,ROW(A9)) | C12: =INDEX('Mod-1 Participant''s Feedback'!$D$59:$HY$59,ROW(A9)) | D12: =INDEX('Mod-1 Participant''s Feedback'!$D$60:$HY$60,ROW(A9))
A13: 10 | B13: =INDEX('Mod-1 Participant''s Feedback'!$D$5:$HY$5,ROW(A10)) | C13: =INDEX('Mod-1 Participant''s Feedback'!$D$59:$HY$59,ROW(A10)) | D13: =INDEX('Mod-1 Participant''s Feedback'!$D$60:$HY$60,ROW(A10))
A14: 11 | B14: =INDEX('Mod-1 Participant''s Feedback'!$D$5:$HY$5,ROW(A11)) | C14: =INDEX('Mod-1 Participant''s Feedback'!$D$59:$HY$59,ROW(A11)) | D14: =INDEX('Mod-1 Participant''s Feedback'!$D$60:$HY$60,ROW(A11))
A15: 12 | B15: =INDEX('Mod-1 Participant''s Feedback'!$D$5:$HY$5,ROW(A12)) | C15: =INDEX('Mod-1 Participant''s Feedback'!$D$59:$HY$59,ROW(A12)) | D15: =INDEX('Mod-1 Participant''s Feedback'!$D$60:$HY$60,ROW(A12))
A16: 13 | B16: =INDEX('Mod-1 Participant''s Feedback'!$D$5:$HY$5,ROW(A13)) | C16: =INDEX('Mod-1 Participant''s Feedback'!$D$59:$HY$59,ROW(A13)) | D16: =INDEX('Mod-1 Participant''s Feedback'!$D$60:$HY$60,ROW(A13))
A17: 14 | B17: =INDEX('Mod-1 Participant''s Feedback'!$D$5:$HY$5,ROW(A14)) | C17: =INDEX('Mod-1 Participant''s Feedback'!$D$59:$HY$59,ROW(A14)) | D17: =INDEX('Mod-1 Participant''s Feedback'!$D$60:$HY$60,ROW(A14))
A18: 15 | B18: =INDEX('Mod-1 Participant''s Feedback'!$D$5:$HY$5,ROW(A15)) | C18: =INDEX('Mod-1 Participant''s Feedback'!$D$59:$HY$59,ROW(A15)) | D18: =INDEX('Mod-1 Participant''s Feedback'!$D$60:$HY$60,ROW(A15))
A19: 16 | B19: =INDEX('Mod-1 Participant''s Feedback'!$D$5:$HY$5,ROW(A16)) | C19: =INDEX('Mod-1 Participant''s Feedback'!$D$59:$HY$59,ROW(A16)) | D19: =INDEX('Mod-1 Participant''s Feedback'!$D$60:$HY$60,ROW(A16))
A20: 17 | B20: =INDEX('Mod-1 Participant''s Feedback'!$D$5:$HY$5,ROW(A17)) | C20: =INDEX('Mod-1 Participant''s Feedback'!$D$59:$HY$59,ROW(A17)) | D20: =INDEX('Mod-1 Participant''s Feedback'!$D$60:$HY$60,ROW(A17))
A21: 18 | B21: =INDEX('Mod-1 Participant''s Feedback'!$D$5:$HY$5,ROW(A18)) | C21: =INDEX('Mod-1 Participant''s Feedback'!$D$59:$HY$59,ROW(A18)) | D21: =INDEX('Mod-1 Participant''s Feedback'!$D$60:$HY$60,ROW(A18))
A22: 19 | B22: =INDEX('Mod-1 Participant''s Feedback'!$D$5:$HY$5,ROW(A19)) | C22: =INDEX('Mod-1 Participant''s Feedback'!$D$59:$HY$59,ROW(A19)) | D22: =INDEX('Mod-1 Participant''s Feedback'!$D$60:$HY$60,ROW(A19))

Sheet Sheet1
A1: UG | B1: SS | C1: PJ | D1: NR | E1: JK
A2: 9.3684211 | B2: 9.1578947 | C2: 8.8947368 | D2: 9.3157895 | E2: 8.8947368
A3: 9.4210526 | B3: 9.0526316 | C3: 8.6315789 | D3: 9.2631579 | E3: 8.4736842
A4: 9.6315789 | B4: 9.5263158 | C4: 9.0526316 | D4: 9.6315789 | E4: 8.6842105
A5: 9.4210526 | B5: 9.1052632 | C5: 8.6842105 | D5: 9.4736842 | E5: 8.8421053
A6: 9.4736842 | B6: 9.1052632 | C6: 8.7368421 | D6: 9.3157895 | E6: 8.5789474
A7: 9.2631579 | B7: 9.1578947 | D7: 9.2631579
A8: 9.3157895 | B8: 8.9473684 | D8: 9.2105263
A9: 9.6315789 | B9: 9.3157895 | D9: 9.5789474
A10: 9.3157895 | B10: 9 | D10: 9.3684211
A11: 9.4736842 | B11: 9.0526316 | D11: 9.3157895
A12: 9.3157895 | B12: 9.1052632
A13: 9.3684211 | B13: 8.9473684
A14: 9.5263158 | B14: 9.5263158
A15: 9.2631579 | B15: 9
A16: 9.5263158 | B16: 9.1052632
A17: =AVERAGE(A2:A16) | B17: =AVERAGE(B2:B16) | C17: =AVERAGE(C2:C16) | D17: =AVERAGE(D2:D16) | E17: =AVERAGE(E2:E16)

Sheet Mod-2 Participant's Feedback
B2: Program | C2: Certified Reliability Engineer - 30 (Date: 06th to 11th July-2026 ) Module - 1
B3: Feedback Form | C3: Please rank the parameters on 10 to 1 scale | D3: 8 to 10 - Excellent ; 6 to 7 - V Good ; 4 to 5 - Good ; 2 to 3- Satisfactory ; 1 - Unsatisfactory
A5: Date | B5: KA / Subject (Name of Faculty) | C5: Criteria | D5: STAFF NO | W5: Avg | X5: Remarks
D6: 214387 | E6: 218036 | F6: 216452 | G6: 217770 | H6: 216676 | I6: 218033 | J6: 217755 | K6: 212842 | L6: 214004 | M6: 216322 | N6: 218114 | O6: 502104N | P6: 217689 | Q6: 502099-K | R6: 216448 | S6: 216168 | T6: 218399 | U6: 216442 | V6: 216449
A7: DAY 1 (20-07-2026) | B7: Reliability Planning (Mr Umesh Ghimirey, Sr.DGM (QM/BAE)) | C7: Course Contenet | D7: 9 | E7: 10 | F7: 10 | G7: 10 | H7: 10 | I7: 10 | J7: 10 | K7: 10 | L7: 10 | M7: 10 | N7: 9 | O7: 10 | P7: 10 | Q7: 10 | R7: 10 | S7: 8 | T7: 8 | U7: 9 | V7: 9 | W7: =AVERAGE(D7:V7) | X7: =IF(W7>=8,"Excellent",IF(W7>=6,"Very good",IF(W7>=4,"Good",IF(W7>=2,"Satisfactory",IF(W7>=1,"Unsatisfactory")))))
C8: Structure & Flow | D8: 9 | E8: 10 | F8: 10 | G8: 10 | H8: 10 | I8: 10 | J8: 10 | K8: 10 | L8: 9 | M8: 10 | N8: 9 | O8: 10 | P8: 9 | Q8: 10 | R8: 10 | S8: 8 | T8: 8 | U8: 9 | V8: 10 | W8: =AVERAGE(D8:V8) | X8: =IF(W8>=8,"Excellent",IF(W8>=6,"Very good",IF(W8>=4,"Good",IF(W8>=2,"Satisfactory",IF(W8>=1,"Unsatisfactory")))))
C9: Time Management | D9: 9 | E9: 10 | F9: 10 | G9: 9 | H9: 10 | I9: 10 | J9: 10 | K9: 10 | L9: 9 | M9: 10 | N9: 9 | O9: 10 | P9: 9 | Q9: 10 | R9: 10 | S9: 8 | T9: 8 | U9: 9 | V9: 10 | W9: =AVERAGE(D9:V9) | X9: =IF(W9>=8,"Excellent",IF(W9>=6,"Very good",IF(W9>=4,"Good",IF(W9>=2,"Satisfactory",IF(W9>=1,"Unsatisfactory")))))
C10: Faculty Delivery | D10: 9 | E10: 10 | F10: 10 | G10: 9 | H10: 10 | I10: 10 | J10: 10 | K10: 10 | L10: 9 | M10: 10 | N10: 9 | O10: 10 | P10: 10 | Q10: 10 | R10: 10 | S10: 8 | T10: 9 | U10: 9 | V10: 10 | W10: =AVERAGE(D10:V10) | X10: =IF(W10>=8,"Excellent",IF(W10>=6,"Very good",IF(W10>=4,"Good",IF(W10>=2,"Satisfactory",IF(W10>=1,"Unsatisfactory")))))
C11: Faculty Participants Interaction | D11: 9 | E11: 10 | F11: 10 | G11: 9 | H11: 10 | I11: 10 | J11: 10 | K11: 10 | L11: 9 | M11: 10 | N11: 9 | O11: 10 | P11: 9 | Q11: 10 | R11: 10 | S11: 8 | T11: 9 | U11: 9 | V11: 10 | W11: =AVERAGE(D11:V11) | X11: =IF(W11>=8,"Excellent",IF(W11>=6,"Very good",IF(W11>=4,"Good",IF(W11>=2,"Satisfactory",IF(W11>=1,"Unsatisfactory")))))
B12: Reliability Testing (Mr Surendra Singh DGM (QM/BAE)) | C12: Course Contenet | D12: 8 | E12: 10 | F12: 10 | G12: 10 | H12: 10 | I12: 10 | J12: 10 | K12: 10 | L12: 9 | M12: 10 | N12: 8 | O12: 10 | P12: 9 | Q12: 8 | R12: 10 | S12: 8 | T12: 9 | U12: 9 | V12: 10 | W12: =AVERAGE(D12:V12) | X12: =IF(W12>=8,"Excellent",IF(W12>=6,"Very good",IF(W12>=4,"Good",IF(W12>=2,"Satisfactory",IF(W12>=1,"Unsatisfactory")))))
C13: Structure & Flow | D13: 7 | E13: 10 | F13: 10 | G13: 9 | H13: 9 | I13: 10 | J13: 10 | K13: 10 | L13: 9 | M13: 10 | N13: 8 | O13: 10 | P13: 9 | Q13: 8 | R13: 10 | S13: 8 | T13: 9 | U13: 9 | V13: 10 | W13: =AVERAGE(D13:V13) | X13: =IF(W13>=8,"Excellent",IF(W13>=6,"Very good",IF(W13>=4,"Good",IF(W13>=2,"Satisfactory",IF(W13>=1,"Unsatisfactory")))))
C14: Time Management | D14: 6 | E14: 9 | F14: 10 | G14: 9 | H14: 10 | I14: 10 | J14: 10 | K14: 10 | L14: 10 | M14: 10 | N14: 8 | O14: 10 | P14: 9 | Q14: 8 | R14: 10 | S14: 8 | T14: 9 | U14: 9 | V14: 10 | W14: =AVERAGE(D14:V14) | X14: =IF(W14>=8,"Excellent",IF(W14>=6,"Very good",IF(W14>=4,"Good",IF(W14>=2,"Satisfactory",IF(W14>=1,"Unsatisfactory")))))
C15: Faculty Delivery | D15: 3 | E15: 10 | F15: 10 | G15: 9 | H15: 9 | I15: 10 | J15: 10 | K15: 10 | L15: 9 | M15: 10 | N15: 8 | O15: 10 | P15: 10 | Q15: 8 | R15: 10 | S15: 8 | T15: 9 | U15: 9 | V15: 10 | W15: =AVERAGE(D15:V15) | X15: =IF(W15>=8,"Excellent",IF(W15>=6,"Very good",IF(W15>=4,"Good",IF(W15>=2,"Satisfactory",IF(W15>=1,"Unsatisfactory")))))
C16: Faculty Participants Interaction | D16: 3 | E16: 10 | F16: 10 | G16: 10 | H16: 10 | I16: 9 | J16: 10 | K16: 9 | L16: 9 | M16: 10 | N16: 8 | O16: 10 | P16: 9 | Q16: 8 | R16: 10 | S16: 8 | T16: 9 | U16: 9 | V16: 10 | W16: =AVERAGE(D16:V16) | X16: =IF(W16>=8,"Excellent",IF(W16>=6,"Very good",IF(W16>=4,"Good",IF(W16>=2,"Satisfactory",IF(W16>=1,"Unsatisfactory")))))
A17: DAY 2 (21-07-2026) | B17: Reliability Testing (Mr Umesh Ghimirey, Sr.DGM (QM/BAE)) | C17: Course Contenet | D17: 8 | E17: 10 | F17: 10 | G17: 10 | H17: 10 | I17: 10 | J17: 10 | K17: 10 | L17: 10 | M17: 10 | N17: 8 | O17: 10 | P17: 9 | Q17: 9 | R17: 10 | S17: 8 | T17: 9 | U17: 10 | V17: 10 | W17: =AVERAGE(D17:V17) | X17: =IF(W17>=8,"Excellent",IF(W17>=6,"Very good",IF(W17>=4,"Good",IF(W17>=2,"Satisfactory",IF(W17>=1,"Unsatisfactory")))))
C18: Structure & Flow | D18: 6 | E18: 10 | F18: 10 | G18: 9 | H18: 10 | I18: 10 | J18: 10 | K18: 9 | L18: 9 | M18: 10 | N18: 8 | O18: 10 | P18: 9 | Q18: 9 | R18: 10 | S18: 8 | T18: 9 | U18: 10 | V18: 9 | W18: =AVERAGE(D18:V18) | X18: =IF(W18>=8,"Excellent",IF(W18>=6,"Very good",IF(W18>=4,"Good",IF(W18>=2,"Satisfactory",IF(W18>=1,"Unsatisfactory")))))
C19: Time Management | D19: 7 | E19: 10 | F19: 10 | G19: 9 | H19: 10 | I19: 10 | J19: 10 | K19: 9 | L19: 9 | M19: 10 | N19: 8 | O19: 10 | P19: 9 | Q19: 9 | R19: 10 | S19: 8 | T19: 9 | U19: 10 | V19: 10 | W19: =AVERAGE(D19:V19) | X19: =IF(W19>=8,"Excellent",IF(W19>=6,"Very good",IF(W19>=4,"Good",IF(W19>=2,"Satisfactory",IF(W19>=1,"Unsatisfactory")))))
C20: Faculty Delivery | D20: 3 | E20: 10 | F20: 10 | G20: 9 | H20: 10 | I20: 10 | J20: 10 | K20: 10 | L20: 9 | M20: 10 | N20: 8 | O20: 10 | P20: 10 | Q20: 9 | R20: 10 | S20: 8 | T20: 9 | U20: 10 | V20: 9 | W20: =AVERAGE(D20:V20) | X20: =IF(W20>=8,"Excellent",IF(W20>=6,"Very good",IF(W20>=4,"Good",IF(W20>=2,"Satisfactory",IF(W20>=1,"Unsatisfactory")))))
C21: Faculty Participants Interaction | D21: 8 | E21: 9 | F21: 10 | G21: 9 | H21: 10 | I21: 9 | J21: 10 | K21: 9 | L21: 9 | M21: 10 | N21: 8 | O21: 10 | P21: 9 | Q21: 9 | R21: 10 | S21: 8 | T21: 9 | U21: 10 | V21: 10 | W21: =AVERAGE(D21:V21) | X21: =IF(W21>=8,"Excellent",IF(W21>=6,"Very good",IF(W21>=4,"Good",IF(W21>=2,"Satisfactory",IF(W21>=1,"Unsatisfactory")))))
B22: Reliability Testing (Mr Narendra S, MGR (BG/PDIC)) | C22: Course Contenet | D22: 9 | E22: 10 | F22: 10 | G22: 10 | H22: 9 | I22: 10 | J22: 10 | K22: 10 | L22: 9 | M22: 10 | N22: 9 | O22: 10 | P22: 9 | Q22: 8 | R22: 10 | S22: 8 | T22: 9 | U22: 10 | V22: 10 | W22: =AVERAGE(D22:V22) | X22: =IF(W22>=8,"Excellent",IF(W22>=6,"Very good",IF(W22>=4,"Good",IF(W22>=2,"Satisfactory",IF(W22>=1,"Unsatisfactory")))))
C23: Structure & Flow | D23: 9 | E23: 10 | F23: 9 | G23: 9 | H23: 9 | I23: 10 | J23: 10 | K23: 9 | L23: 9 | M23: 10 | N23: 9 | O23: 10 | P23: 9 | Q23: 8 | R23: 10 | S23: 8 | T23: 9 | U23: 9 | V23: 9 | W23: =AVERAGE(D23:V23) | X23: =IF(W23>=8,"Excellent",IF(W23>=6,"Very good",IF(W23>=4,"Good",IF(W23>=2,"Satisfactory",IF(W23>=1,"Unsatisfactory")))))
C24: Time Management | D24: 9 | E24: 10 | F24: 9 | G24: 8 | H24: 9 | I24: 10 | J24: 10 | K24: 9 | L24: 10 | M24: 10 | N24: 9 | O24: 10 | P24: 9 | Q24: 8 | R24: 10 | S24: 8 | T24: 9 | U24: 10 | V24: 9 | W24: =AVERAGE(D24:V24) | X24: =IF(W24>=8,"Excellent",IF(W24>=6,"Very good",IF(W24>=4,"Good",IF(W24>=2,"Satisfactory",IF(W24>=1,"Unsatisfactory")))))
C25: Faculty Delivery | D25: 9 | E25: 10 | F25: 9 | G25: 9 | H25: 9 | I25: 10 | J25: 10 | K25: 9 | L25: 9 | M25: 10 | N25: 9 | O25: 10 | P25: 10 | Q25: 8 | R25: 10 | S25: 8 | T25: 9 | U25: 10 | V25: 10 | W25: =AVERAGE(D25:V25) | X25: =IF(W25>=8,"Excellent",IF(W25>=6,"Very good",IF(W25>=4,"Good",IF(W25>=2,"Satisfactory",IF(W25>=1,"Unsatisfactory")))))
C26: Faculty Participants Interaction | D26: 9 | E26: 10 | F26: 9 | G26: 9 | H26: 9 | I26: 10 | J26: 10 | K26: 9 | L26: 9 | M26: 10 | N26: 9 | O26: 10 | P26: 9 | Q26: 8 | R26: 10 | S26: 8 | T26: 9 | U26: 10 | V26: 10 | W26: =AVERAGE(D26:V26) | X26: =IF(W26>=8,"Excellent",IF(W26>=6,"Very good",IF(W26>=4,"Good",IF(W26>=2,"Satisfactory",IF(W26>=1,"Unsatisfactory")))))
A27: DAY 3 (22-07-2026) | B27: Reliability Modelling (Mr Umesh Ghimirey, Sr.DGM (QM/BAE)) | C27: Course Contenet | D27: 9 | E27: 10 | F27: 10 | G27: 10 | H27: 10 | I27: 10 | J27: 10 | K27: 10 | L27: 9 | M27: 10 | N27: 9 | O27: 10 | P27: 10 | Q27: 10 | R27: 10 | S27: 8 | T27: 8 | U27: 10 | V27: 10 | W27: =AVERAGE(D27:V27) | X27: =IF(W27>=8,"Excellent",IF(W27>=6,"Very good",IF(W27>=4,"Good",IF(W27>=2,"Satisfactory",IF(W27>=1,"Unsatisfactory")))))
C28: Structure & Flow | D28: 9 | E28: 10 | F28: 10 | G28: 10 | H28: 10 | I28: 10 | J28: 10 | K28: 10 | L28: 9 | M28: 10 | N28: 9 | O28: 10 | P28: 9 | Q28: 10 | R28: 10 | S28: 8 | T28: 8 | U28: 10 | V28: 10 | W28: =AVERAGE(D28:V28) | X28: =IF(W28>=8,"Excellent",IF(W28>=6,"Very good",IF(W28>=4,"Good",IF(W28>=2,"Satisfactory",IF(W28>=1,"Unsatisfactory")))))
C29: Time Management | D29: 9 | E29: 9 | F29: 10 | G29: 10 | H29: 10 | I29: 10 | J29: 10 | K29: 10 | L29: 10 | M29: 10 | N29: 9 | O29: 10 | P29: 10 | Q29: 10 | R29: 10 | S29: 8 | T29: 7 | U29: 10 | V29: 10 | W29: =AVERAGE(D29:V29) | X29: =IF(W29>=8,"Excellent",IF(W29>=6,"Very good",IF(W29>=4,"Good",IF(W29>=2,"Satisfactory",IF(W29>=1,"Unsatisfactory")))))
C30: Faculty Delivery | D30: 9 | E30: 10 | F30: 10 | G30: 10 | H30: 10 | I30: 10 | J30: 10 | K30: 10 | L30: 9 | M30: 10 | N30: 9 | O30: 10 | P30: 10 | Q30: 10 | R30: 10 | S30: 8 | T30: 8 | U30: 10 | V30: 10 | W30: =AVERAGE(D30:V30) | X30: =IF(W30>=8,"Excellent",IF(W30>=6,"Very good",IF(W30>=4,"Good",IF(W30>=2,"Satisfactory",IF(W30>=1,"Unsatisfactory")))))
C31: Faculty Participants Interaction | D31: 9 | E31: 10 | F31: 10 | G31: 10 | H31: 10 | I31: 10 | J31: 10 | K31: 10 | L31: 9 | M31: 10 | N31: 9 | O31: 10 | P31: 10 | Q31: 10 | R31: 10 | S31: 8 | T31: 9 | U31: 10 | V31: 10 | W31: =AVERAGE(D31:V31) | X31: =IF(W31>=8,"Excellent",IF(W31>=6,"Very good",IF(W31>=4,"Good",IF(W31>=2,"Satisfactory",IF(W31>=1,"Unsatisfactory")))))
B32: Quiz on CRE (Mr Umesh Ghimirey, Sr.DGM (QM/BAE)) | C32: Relevance of the Quiz to the Topics | D32: 10 | E32: 10 | F32: 10 | G32: 10 | H32: 10 | I32: 10 | J32: 10 | K32: 10 | L32: 9 | M32: 10 | N32: 9 | O32: 10 | P32: 10 | Q32: 10 | R32: 10 | S32: 8 | T32: 10 | U32: 10 | V32: 9 | W32: =AVERAGE(D32:V32) | X32: =IF(W32>=8,"Excellent",IF(W32>=6,"Very good",IF(W32>=4,"Good",IF(W32>=2,"Satisfactory",IF(W32>=1,"Unsatisfactory")))))
C33: Innovativeness in Presentation Method | D33: 10 | E33: 10 | F33: 10 | G33: 10 | H33: 9 | I33: 10 | J33: 10 | K33: 10 | L33: 9 | M33: 10 | N33: 9 | O33: 10 | P33: 10 | Q33: 10 | R33: 10 | S33: 8 | T33: 10 | U33: 10 | V33: 9 | W33: =AVERAGE(D33:V33) | X33: =IF(W33>=8,"Excellent",IF(W33>=6,"Very good",IF(W33>=4,"Good",IF(W33>=2,"Satisfactory",IF(W33>=1,"Unsatisfactory")))))
C34: Quiz Master's Effectiveness | D34: 10 | E34: 10 | F34: 10 | G34: 10 | H34: 9 | I34: 10 | J34: 10 | K34: 10 | L34: 9 | M34: 10 | N34: 9 | O34: 10 | P34: 10 | Q34: 10 | R34: 10 | S34: 8 | T34: 10 | U34: 10 | V34: 9 | W34: =AVERAGE(D34:V34) | X34: =IF(W34>=8,"Excellent",IF(W34>=6,"Very good",IF(W34>=4,"Good",IF(W34>=2,"Satisfactory",IF(W34>=1,"Unsatisfactory")))))
C35: Overall impresion of the Quiz in Learning | D35: 10 | E35: 10 | F35: 10 | G35: 10 | H35: 9 | I35: 10 | J35: 10 | K35: 10 | L35: 9 | M35: 10 | N35: 9 | O35: 10 | P35: 10 | Q35: 10 | R35: 10 | S35: 8 | T35: 10 | U35: 10 | V35: 9 | W35: =AVERAGE(D35:V35) | X35: =IF(W35>=8,"Excellent",IF(W35>=6,"Very good",IF(W35>=4,"Good",IF(W35>=2,"Satisfactory",IF(W35>=1,"Unsatisfactory")))))
B36: Failure Models (Mr. Faiz Ahmed Siddiqui (MGR/MILCOM)) | C36: Course Contenet | D36: 2 | E36: 8 | F36: 6 | G36: 8 | H36: 9 | I36: 8 | J36: 6 | K36: 10 | L36: 8 | M36: 10 | N36: 5 | O36: 10 | P36: 7 | Q36: 5 | R36: 10 | S36: 8 | T36: 7 | U36: 7 | V36: 8 | W36: =AVERAGE(D36:V36) | X36: =IF(W36>=8,"Excellent",IF(W36>=6,"Very good",IF(W36>=4,"Good",IF(W36>=2,"Satisfactory",IF(W36>=1,"Unsatisfactory")))))
C37: Structure & Flow | D37: 2 | E37: 8 | F37: 5 | G37: 8 | H37: 9 | I37: 7 | J37: 6 | K37: 9 | L37: 9 | M37: 9 | N37: 5 | O37: 8 | P37: 8 | Q37: 5 | R37: 10 | S37: 8 | T37: 7 | U37: 7 | V37: 8 | W37: =AVERAGE(D37:V37) | X37: =IF(W37>=8,"Excellent",IF(W37>=6,"Very good",IF(W37>=4,"Good",IF(W37>=2,"Satisfactory",IF(W37>=1,"Unsatisfactory")))))
C38: Time Management | D38: 2 | E38: 8 | F38: 4 | G38: 7 | H38: 8 | I38: 7 | J38: 6 | K38: 9 | L38: 9 | M38: 10 | N38: 5 | O38: 8 | P38: 9 | Q38: 5 | R38: 10 | S38: 8 | T38: 6 | U38: 7 | V38: 7 | W38: =AVERAGE(D38:V38) | X38: =IF(W38>=8,"Excellent",IF(W38>=6,"Very good",IF(W38>=4,"Good",IF(W38>=2,"Satisfactory",IF(W38>=1,"Unsatisfactory")))))
C39: Faculty Delivery | D39: 2 | E39: 9 | F39: 5 | G39: 7 | H39: 8 | I39: 10 | J39: 6 | K39: 10 | L39: 8 | M39: 10 | N39: 5 | O39: 8 | P39: 8 | Q39: 5 | R39: 10 | S39: 8 | T39: 7 | U39: 7 | V39: 8 | W39: =AVERAGE(D39:V39) | X39: =IF(W39>=8,"Excellent",IF(W39>=6,"Very good",IF(W39>=4,"Good",IF(W39>=2,"Satisfactory",IF(W39>=1,"Unsatisfactory")))))
C40: Faculty Participants Interaction | D40: 6 | E40: 10 | F40: 5 | G40: 8 | H40: 8 | I40: 10 | J40: 6 | K40: 9 | L40: 8 | M40: 10 | N40: 5 | O40: 9 | P40: 8 | Q40: 5 | R40: 10 | S40: 8 | T40: 8 | U40: 7 | V40: 8 | W40: =AVERAGE(D40:V40) | X40: =IF(W40>=8,"Excellent",IF(W40>=6,"Very good",IF(W40>=4,"Good",IF(W40>=2,"Satisfactory",IF(W40>=1,"Unsatisfactory")))))
A41: DAY 4 (23-07-2026) | B41: Reliability Prediction Methods, Design Prototype (Mrs Pidathal Jahnavi DM (BG/MS)) | C41: Course Contenet | D41: 6 | E41: 9 | F41: 9 | G41: 10 | H41: 9 | I41: 10 | J41: 10 | K41: 10 | L41: 9 | M41: 10 | N41: 9 | O41: 9 | P41: 10 | Q41: 5 | R41: 10 | S41: 8 | T41: 9 | U41: 10 | V41: 9 | W41: =AVERAGE(D41:V41) | X41: =IF(W41>=8,"Excellent",IF(W41>=6,"Very good",IF(W41>=4,"Good",IF(W41>=2,"Satisfactory",IF(W41>=1,"Unsatisfactory")))))
C42: Structure & Flow | D42: 6 | E42: 8 | F42: 9 | G42: 10 | H42: 9 | I42: 10 | J42: 10 | K42: 10 | L42: 9 | M42: 10 | N42: 9 | O42: 10 | P42: 9 | Q42: 5 | R42: 10 | S42: 8 | T42: 9 | U42: 10 | V42: 9 | W42: =AVERAGE(D42:V42) | X42: =IF(W42>=8,"Excellent",IF(W42>=6,"Very good",IF(W42>=4,"Good",IF(W42>=2,"Satisfactory",IF(W42>=1,"Unsatisfactory")))))
...

Sheet Mod-2 Overall Feedback
B4: Staff No | C4: ='Mod-2 Participant''s Feedback'!D6 | D4: ='Mod-2 Participant''s Feedback'!E6 | E4: ='Mod-2 Participant''s Feedback'!F6 | F4: ='Mod-2 Participant''s Feedback'!G6 | G4: ='Mod-2 Participant''s Feedback'!H6 | H4: ='Mod-2 Participant''s Feedback'!I6 | I4: ='Mod-2 Participant''s Feedback'!J6 | J4: ='Mod-2 Participant''s Feedback'!K6 | ... U4: ='Mod-2 Participant''s Feedback'!V6 | V4: Avr
B5: Delivery Notes (Course Material) | C5: ='Mod-2 Participant''s Feedback'!D61 | D5: ='Mod-2 Participant''s Feedback'!E61 | E5: ='Mod-2 Participant''s Feedback'!F61 | F5: ='Mod-2 Participant''s Feedback'!G61 | G5: ='Mod-2 Participant''s Feedback'!H61 | H5: ='Mod-2 Participant''s Feedback'!I61 | I5: ='Mod-2 Participant''s Feedback'!J61 | J5: ='Mod-2 Participant''s Feedback'!K61 | ... U5: ='Mod-2 Participant''s Feedback'!V61 | V5: =AVERAGE(C5:U5)
B6: Communication & Overall Coordination | C6: ='Mod-2 Participant''s Feedback'!D62 | D6: ='Mod-2 Participant''s Feedback'!E62 | E6: ='Mod-2 Participant''s Feedback'!F62 | F6: ='Mod-2 Participant''s Feedback'!G62 | G6: ='Mod-2 Participant''s Feedback'!H62 | H6: ='Mod-2 Participant''s Feedback'!I62 | I6: ='Mod-2 Participant''s Feedback'!J62 | J6: ='Mod-2 Participant''s Feedback'!K62 | ... U6: ='Mod-2 Participant''s Feedback'!V62 | V6: =AVERAGE(C6:U6)
B7: Classroom Facilities | C7: ='Mod-2 Participant''s Feedback'!D63 | D7: ='Mod-2 Participant''s Feedback'!E63 | E7: ='Mod-2 Participant''s Feedback'!F63 | F7: ='Mod-2 Participant''s Feedback'!G63 | G7: ='Mod-2 Participant''s Feedback'!H63 | H7: ='Mod-2 Participant''s Feedback'!I63 | I7: ='Mod-2 Participant''s Feedback'!J63 | J7: ='Mod-2 Participant''s Feedback'!K63 | ... U7: ='Mod-2 Participant''s Feedback'!V63 | V7: =AVERAGE(C7:U7)
B8: Relevance to your current job | C8: ='Mod-2 Participant''s Feedback'!D64 | D8: ='Mod-2 Participant''s Feedback'!E64 | E8: ='Mod-2 Participant''s Feedback'!F64 | F8: ='Mod-2 Participant''s Feedback'!G64 | G8: ='Mod-2 Participant''s Feedback'!H64 | H8: ='Mod-2 Participant''s Feedback'!I64 | I8: ='Mod-2 Participant''s Feedback'!J64 | J8: ='Mod-2 Participant''s Feedback'!K64 | ... U8: ='Mod-2 Participant''s Feedback'!V64 | V8: =AVERAGE(C8:U8)

Sheet Mod-2 Suggestions
A1: Certified Reliability Engineer - 30 (Date: 20th to 25th Jun-2026 )
A2: Overall Program Feedback
A3: SL No | B3: Staff No | C3: What are the other quality training programs you want us to add in training calender ? | D3: Any Suggestions for the future program ?
A4: 1 | B4: 217770 | D4: Reorganization of Course material of Module 2 as per topic flow.
A5: 2 | B5: 216442 | D5: Module-2 slides were not aligned, which created some confusion.
A6: 3 | B6: 218036 | D6: Focus on complex topics with practical examples for better concept understanding.
A7: 4 | B7: 216452 | D7: Explain the background of Formulas to provide better context ("feel").
A8: 5 | B8: 218399 | D8: Duration for complex topics like DOE & Reliability Modelling can be increased.
A9: 6 | B9: 216322 | D9: Please provide soft copy of class ppt notes.
A10: 7 | B10: 216448 | D10: Continue the Good Work.

Sheet Sheet 2
B4: UG | C4: SS | D4: NS | E4: PJ | F4: FA | G4: JK
B17: 9.65 | C17: 9.28 | D17: 9.22 | E17: 9.07 | F17: 8.97 | G17: 7.33

Sheet Shedule
A1: BEL Academy for Excellence
A2: Certified Reliability Engineer Training Program - Batch 30 Module 2 : 20th - 25th July 2026 (Tungabhadra Hall at Nalanda:BAE, Bengaluru)
A3: Course Co-ordinator: Umesh Ghimirey, Sr.DGM (QM/BAE)
A4: Date | B4: Session Time | C4: Session / Knowledge Area | D4: Name of The Faculty
A5: 46223 | B5: 1) 08:30 --- 10:00 | C5: Reliability Planning | D5: Mr. Umesh Ghimirey, Sr.DGM (QM/BAE)
B6: 2) 10:15 --- 11:30
B7: 3) 11:45 --- 12:45 | C7: Reliability Testing | D7: Mr. Surendra Singh, DGM (QM/BAE)
B8: 4) 13:30 --- 14:45
B9: 5) 15:00 --- 16:50
A10: =+A5+1 | B10: 1) 08:30 --- 10:00 | C10: Reliability Testing | D10: Mr. Surendra Singh, DGM (QM/BAE)
B11: 2) 10:15 --- 11:30
B12: 3) 11:45 --- 12:45
B13: 4) 13:30 --- 14:45 | C13: Reliability Testing | D13: Mr. Narendra S, MGR/PDIC
B14: 5) 15:00 --- 16:50
A15: =+A10+1 | B15: 1) 08:30 --- 10:00 | C15: Reliability Modelling | D15: Mr. Umesh Ghimirey, Sr.DGM (QM/BAE)
B16: 2) 10:15 --- 11:30
B17: 3) 11:45 --- 12:45
B18: 4) 13:30 --- 14:45
B19: 5) 15:00 --- 16:50 | C19: Failure Models | D19: Mr. Faiz Ahmed Siddiqui MGR/MILCOM
A20: =+A15+1 | B20: 1) 08:30 --- 10:00 | C20: Reliability Prediction Methods, Design Prototype | D20: Mrs. Pidathala Jahnavi (DM/MS)
B21: 2) 10:15 --- 11:30
B22: 3) 11:45 --- 12:45 | C22: Reliability Design Techniques & Parts and Systems Development | D22: Mr. Faiz Ahmed Siddiqui (MGR/MILCOM)
B23: 4) 13:30 --- 14:45
B24: 5) 15:00 --- 16:50
A25: =+A20+1 | B25: 1) 08:30 --- 10:00 | C25: Reliability Design Techniques (DOE) | D25: Mr. Surendra Singh, DGM (QM/BAE)
B26: 2) 10:15 --- 11:30
B27: 3) 11:45 --- 12:45
B28: 4) 13:30 --- 14:45 | C28: Maintainability | D28: Mr. Jagadeesh K R External Faculty
B29: 5) 15:00 --- 16:50
A30: =+A25+1 | B30: 1) 08:30 --- 09:15 | C30: Quiz on CRE | D30: Mr. Umesh Ghimirey, Sr.DGM (QM/BAE)
B31: 2) 09:15 --- 10:30 | C31: Revision & Exam Briefing
B32: 3) 10:30 --- 12:45 | C32: Training Assessment-2
B33: 4) 13:30 --- 16:50 | C33: Discussion on Assessment-2
A34: Tea/Coffee Break (15 Minutes) | C34: [I - 10:00 to 10:15] [II - 11:30 to 11:45] [III - 14:45 to 15:00]
A35: Lunch Break (45 Minutes) | C35: 12:45-13:30 Hrs
A36: Sr.DGM & Head Quality Wing
A37: CC: AGM & Head BAE All Concerned Faculties
